Workbook

Sheet Cover Page
B2: Ambulatory Surgery Center Development with 2 Robotic Systems Capital Budgeting, Volume Ramp, Operating Cost, Cash Flow, and DCF Analysis
C7: Content
C10: Dashboard
C11: Input
C12: Scenarios
C13: Capex
C14: Volume
C15: Revenue
C16: Opex
C17: P&L
C18: Cash Flow
C19: DCF

Sheet Dashboard
B2: Project Dashboard
C8: Scenario
C10: NPV | D10: =DCF!C12 -> 5586255.4
C12: Year 5 Revenue | D12: ='P&L'!$H$8 -> 1.0966881e+08
C13: Year 5 EBITDA | D13: ='P&L'!$H$13 -> 59741565
C14: Year 5 EBITDA Margin | D14: ='P&L'!$H$21 -> 0.54474528
C16: Year 5 Delivered Cases | D16: =Volume!$H$14 -> 6922.3725
C17: Year 5 Robotic Cases | D17: =Volume!$H$25 -> 1747.8991
C40: Metric | D40: Y1 | E40: Y2 | F40: Y3 | G40: Y4 | H40: Y5 | I40: Y6 | J40: Y7 | K40: Y8 | L40: Y9 | M40: Y10
C41: Revenue | D41: =Revenue!D9 -> 28119360 | E41: =Revenue!E9 -> 76115970 | F41: =Revenue!F9 -> 97439315 | G41: =Revenue!G9 -> 1.0337337e+08 | H41: =Revenue!H9 -> 1.0966881e+08 | I41: =Revenue!I9 -> 1.1634764e+08 | J41: =Revenue!J9 -> 1.2343321e+08 | K41: =Revenue!K9 -> 1.3095029e+08 | ... M41: =Revenue!M9 -> 1.4738571e+08
C42: EBITDA | D42: ='P&L'!$D$13 -> 4812655.6 | E42: ='P&L'!$E$13 -> 39393570 | F42: ='P&L'!F13 -> 52572939 | G42: ='P&L'!G13 -> 56047365 | H42: ='P&L'!H13 -> 59741565 | I42: ='P&L'!I13 -> 63669170 | J42: ='P&L'!J13 -> 67844647 | K42: ='P&L'!K13 -> 72283351 | L42: ='P&L'!L13 -> 77001580 | M42: ='P&L'!M13 -> 82016635
C43: Delivered Cases | D43: =Volume!D14 -> 3000 | E43: =Volume!E14 -> 5250 | F43: =Volume!F14 -> 6525 | G43: =Volume!G14 -> 6720.75 | H43: =Volume!H14 -> 6922.3725 | I43: =Volume!I14 -> 7130.0437 | J43: =Volume!J14 -> 7343.945 | K43: =Volume!K14 -> 7564.2633 | ... M43: =Volume!M14 -> 8024.927

Sheet Input
B2: Key Model Assumptions & Inputs
B6: Project Model & Finances | C6: Value | D6: Notes
B7: Discount Rate (WACC) | C7: 0.12 | D7: Used for NPV.
B8: Corporate Tax Rate | C8: 0.25 | D8: Applied to EBIT for unlevered FCF.
B9: Inflation Rate (Opex) | C9: 0.03 | D9: Annual inflation for salaries & fixed costs after opening.
B10: Inflation Rate (Reimbursement) | C10: 0.03 | D10: Annual reimbursement inflation after opening.
B11: Volume Growth | C11: 0.03 | D11: Annual growth after ramp complete
B12: Facility Ops | C12: 0.04 | D12: (utilities, insurance, maintenance) – % of revenue
B14: Facility/Capacity Assumptions | C14: Value | D14: Notes
B15: Facility Size (sq ft) | C15: 34000
B16: # OR | C16: 4
B17: # Procedure Rooms | C17: 3
B18: Operating Days/Year | C18: 240
B19: OR cases/OR day | C19: 7
B20: Procedure Cases/Room/Day | C20: 4
B21: OR utilization at steady state | C21: 0.85 | D21: % of theoretical capacity.
B22: procedure room utilization at steady state | C22: 0.85
B23: average turnover time (minutes) | C23: 25
B25: CAPEX Assumptions | C25: Value | D25: Notes
B26: construction cost($/sq ft) | C26: 600
B27: sofr cost (% of construction) | C27: 0.15 | D27: Design/permits/FF&E project mgmt.
B28: Risk Buffer | C28: 0.15 | D28: % of hard costs
B29: # Robotic Systems | C29: 2 | D29: da Vinci Xi
B30: Robot Purchases Price (each) | C30: 1450000 | D30: Per robot purchase cost assumption.
B31: robot annual service contract (each) | C31: 150000 | D31: Annual service contract example from a federal procurement listing.
B32: other medical equipment (lump sum) | C32: 4450000 | D32: Anesthesia machines, tables, scopes, sterilization, imaging, etc.
B33: IT intergration (lump sum) | C33: 385000 | D33: EHR interfaces, scheduling, networking, analytics.
B34: working capital at opening (% of year 1 revenue) | C34: 0.02 | D34: Initial net working capital investment.
B36: OPEX Assumptions
B37: Robotic disposables cost/case | C37: 1500
B38: Marketing/Referral | C38: 300000
B40: Staffing Assumptions
B41: Role | C41: FTE | D41: Base Salary | E41: Benefits Load | F41: Fully-loaded $/FTE
B42: RN/PACU | C42: 30 | D42: 90000 | E42: 0.28 | F42: =(D42)*(1+E42) -> 115200
B43: Surgical Tech | C43: 18 | D43: 65000 | E43: 0.28 | F43: =(D43)*(1+E43) -> 83200
B44: Sterile Processing Tech | C44: 8 | D44: 51000 | E44: 0.28 | F44: =(D44)*(1+E44) -> 65280
B45: Radiology/Imaging Tech (float) | C45: 4 | D45: 78000 | E45: 0.28 | F45: =(D45)*(1+E45) -> 99840
B46: Pre-op / Admissions / Front Desk | C46: 9 | D46: 55000 | E46: 0.28 | F46: =(D46)*(1+E46) -> 70400
B47: Materials / Supply Chain | C47: 4 | D47: 62000 | E47: 0.28 | F47: =(D47)*(1+E47) -> 79360
B48: Facility Manager / Biomed | C48: 2 | D48: 95000 | E48: 0.28 | F48: =(D48)*(1+E48) -> 121600
...

Sheet Scenarios
B2: Scenarios
B5: Scenario | C5: Comm% | D5: Medicare% | E5: Medicaid% | F5: Self-pay% | G5: Ramp Y1 | H5: Ramp Y2
B6: Base Case | C6: 0.28 | D6: 0.47 | E6: 0.2 | F6: 0.05 | G6: 0.4 | H6: 0.7
B7: High Commercial Mix | C7: 0.45 | D7: 0.35 | E7: 0.15 | F7: 0.05 | G7: 0.4 | H7: 0.7
B8: Medicare Shift | C8: 0.25 | D8: 0.55 | E8: 0.15 | F8: 0.05 | G8: 0.4 | H8: 0.7
B9: Fast Ramp | C9: 0.28 | D9: 0.47 | E9: 0.2 | F9: 0.05 | G9: 0.5 | H9: 0.8
B10: Slow Ramp | C10: 0.28 | D10: 0.47 | E10: 0.2 | F10: 0.05 | G10: 0.3 | H10: 0.55

Sheet Capex
B2: Capital Expenditures & Depreciation Schedule
B6: Line Item | C6: Y0 | D6: Y1 | E6: Y2 | F6: Y3 | G6: Y4 | H6: Y5 | I6: Y6 | J6: Y7 | K6: Y8 | L6: Y9 | M6: Y10
B7: Construction Hard Cost | C7: =Input!C15*Input!C26 -> 20400000 | D7: 0 | E7: 0 | F7: 0 | G7: 0 | H7: 0 | I7: 0 | J7: 0 | K7: 0 | L7: 0 | M7: 0
B8: Soft Costs (% Of Construction) | C8: =Input!C15*Input!C26*Input!C27 -> 3060000 | D8: 0 | E8: 0 | F8: 0 | G8: 0 | H8: 0 | I8: 0 | J8: 0 | K8: 0 | L8: 0 | M8: 0
B9: Robotic Purchase | C9: =Input!C30*Input!C29 -> 2900000 | D9: 0 | E9: 0 | F9: 0 | G9: 0 | H9: 0 | I9: 0 | J9: 0 | K9: 0 | L9: 0 | M9: 0
B10: Other Medical Equipment | C10: =Input!C32 -> 4450000
B11: It Integration | C11: =Input!C33 -> 385000 | D11: 0 | E11: 0 | F11: 0 | G11: 0 | H11: 0 | I11: 0 | J11: 0 | K11: 0 | L11: 0 | M11: 0
B12: Subtotal (Hard + Soft) | C12: =SUM(C7:C11) -> 31195000 | D12: 0 | E12: 0 | F12: 0 | G12: 0 | H12: 0 | I12: 0 | J12: 0 | K12: 0 | L12: 0 | M12: 0
B13: Risk Buffer | C13: =C12*Input!C28 -> 4679250 | D13: 0 | E13: 0 | F13: 0 | G13: 0 | H13: 0 | I13: 0 | J13: 0 | K13: 0 | L13: 0 | M13: 0
B14: Total CAPEX | C14: =C12+C13 -> 35874250 | D14: 0 | E14: 0 | F14: 0 | G14: 0 | H14: 0 | I14: 0 | J14: 0 | K14: 0 | L14: 0 | M14: 0
B17: Depreciatin | C17: Y0 | D17: Y1 | E17: Y2 | F17: Y3 | G17: Y4 | H17: Y5 | I17: Y6 | J17: Y7 | K17: Y8 | L17: Y9 | M17: Y10
B18: Building Useful Life (Years) | C18: 20
B19: Equipment Useful Life (Years) | C19: 10
B20: Building Depreciation | C20: 0 | D20: =SUM($C$7:$M$7)/$C$18 -> 1020000 | E20: =SUM($C$7:$M$7)/$C$18 -> 1020000 | F20: =SUM($C$7:$M$7)/$C$18 -> 1020000 | G20: =SUM($C$7:$M$7)/$C$18 -> 1020000 | H20: =SUM($C$7:$M$7)/$C$18 -> 1020000 | I20: =SUM($C$7:$M$7)/$C$18 -> 1020000 | J20: =SUM($C$7:$M$7)/$C$18 -> 1020000 | K20: =SUM($C$7:$M$7)/$C$18 -> 1020000 | ... M20: =SUM($C$7:$M$7)/$C$18 -> 1020000
B21: Equipment Depreciation | C21: 0 | D21: =SUM($C$9:$M$11)/$C$19 -> 773500 | E21: =SUM($C$9:$M$11)/$C$19 -> 773500 | F21: =SUM($C$9:$M$11)/$C$19 -> 773500 | G21: =SUM($C$9:$M$11)/$C$19 -> 773500 | H21: =SUM($C$9:$M$11)/$C$19 -> 773500 | I21: =SUM($C$9:$M$11)/$C$19 -> 773500 | J21: =SUM($C$9:$M$11)/$C$19 -> 773500 | K21: =SUM($C$9:$M$11)/$C$19 -> 773500 | ... M21: =SUM($C$9:$M$11)/$C$19 -> 773500
B22: Total Depreciation | C22: 0 | D22: =SUM(D20:D21) -> 1793500 | E22: =SUM(E20:E21) -> 1793500 | F22: =SUM(F20:F21) -> 1793500 | G22: =SUM(G20:G21) -> 1793500 | H22: =SUM(H20:H21) -> 1793500 | I22: =SUM(I20:I21) -> 1793500 | J22: =SUM(J20:J21) -> 1793500 | K22: =SUM(K20:K21) -> 1793500 | ... M22: =SUM(M20:M21) -> 1793500

Sheet Volume
B2: Volume Ramp & Case Capacity Analysis
C5: Scenario Control | D5: 1
B7: Metric | C7: Y0 | D7: Y1 | E7: Y2 | F7: Y3 | G7: Y4 | H7: Y5 | I7: Y6 | J7: Y7 | K7: Y8 | L7: Y9 | M7: Y10
B8: Cases/Year | C8: 0 | D8: 7500 | E8: 7500 | F8: 7500 | G8: 7500 | H8: 7500 | I8: 7500 | J8: 7500 | K8: 7500 | L8: 7500 | M8: 7500
B9: Ramp Factor | C9: 0 | D9: {=INDEX(Scenarios!$G$6:$G$10,$D$5)} -> 0.4 | E9: {=INDEX(Scenarios!$H$6:$H$10,$D$5)} -> 0.7 | F9: 0.87 | G9: =F9*1.03 -> 0.8961 | H9: =G9*1.03 -> 0.922983 | I9: =H9*1.03 -> 0.95067249 | J9: =I9*1.03 -> 0.97919266 | K9: =J9*1.03 -> 1.0085684 | L9: =K9*1.03 -> 1.0388255 | M9: =L9*1.03 -> 1.0699903
B10: Demanded Cases | C10: 0 | D10: =D8*D9 -> 3000 | E10: =E8*E9 -> 5250 | F10: =F8*F9 -> 6525 | G10: =G8*G9 -> 6720.75 | H10: =H8*H9 -> 6922.3725 | I10: =I8*I9 -> 7130.0437 | J10: =J8*J9 -> 7343.945 | K10: =K8*K9 -> 7564.2633 | ... M10: =M8*M9 -> 8024.927
B11: Or Capacity | C11: 0 | D11: =Input!$C$16*Input!$C$18*Input!$C$19*Input!$C$21 -> 5712 | E11: =Input!$C$16*Input!$C$18*Input!$C$19*Input!$C$21 -> 5712 | F11: =Input!$C$16*Input!$C$18*Input!$C$19*Input!$C$21 -> 5712 | G11: =Input!$C$16*Input!$C$18*Input!$C$19*Input!$C$21 -> 5712 | H11: =Input!$C$16*Input!$C$18*Input!$C$19*Input!$C$21 -> 5712 | I11: =Input!$C$16*Input!$C$18*Input!$C$19*Input!$C$21 -> 5712 | J11: =Input!$C$16*Input!$C$18*Input!$C$19*Input!$C$21 -> 5712 | K11: =Input!$C$16*Input!$C$18*Input!$C$19*Input!$C$21 -> 5712 | ... M11: =Input!$C$16*Input!$C$18*Input!$C$19*Input!$C$21 -> 5712
B12: Procedure Room Capacity/Year | C12: 0 | D12: =Input!$C$17*Input!$C$20*Input!$C$22*Input!$C$18 -> 2448 | E12: =Input!$C$17*Input!$C$20*Input!$C$22*Input!$C$18 -> 2448 | F12: =Input!$C$17*Input!$C$20*Input!$C$22*Input!$C$18 -> 2448 | G12: =Input!$C$17*Input!$C$20*Input!$C$22*Input!$C$18 -> 2448 | H12: =Input!$C$17*Input!$C$20*Input!$C$22*Input!$C$18 -> 2448 | I12: =Input!$C$17*Input!$C$20*Input!$C$22*Input!$C$18 -> 2448 | J12: =Input!$C$17*Input!$C$20*Input!$C$22*Input!$C$18 -> 2448 | K12: =Input!$C$17*Input!$C$20*Input!$C$22*Input!$C$18 -> 2448 | ... M12: =Input!$C$17*Input!$C$20*Input!$C$22*Input!$C$18 -> 2448
B13: Total Capacity/Year | C13: 0 | D13: =SUM(D11:D12) -> 8160 | E13: =SUM(E11:E12) -> 8160 | F13: =SUM(F11:F12) -> 8160 | G13: =SUM(G11:G12) -> 8160 | H13: =SUM(H11:H12) -> 8160 | I13: =SUM(I11:I12) -> 8160 | J13: =SUM(J11:J12) -> 8160 | K13: =SUM(K11:K12) -> 8160 | ... M13: =SUM(M11:M12) -> 8160
B14: Delivered Cases | C14: 0 | D14: =MIN(D10,D13) -> 3000 | E14: =MIN(E10,E13) -> 5250 | F14: =MIN(F10,F13) -> 6525 | G14: =MIN(G10,G13) -> 6720.75 | H14: =MIN(H10,H13) -> 6922.3725 | I14: =MIN(I10,I13) -> 7130.0437 | J14: =MIN(J10,J13) -> 7343.945 | K14: =MIN(K10,K13) -> 7564.2633 | ... M14: =MIN(M10,M13) -> 8024.927
B17: Delivered Cases By Specialty (Based On Inputs Mix %) | C17: Y0 | D17: Y1 | E17: Y2 | F17: Y3 | G17: Y4 | H17: Y5 | I17: Y6 | J17: Y7 | K17: Y8 | L17: Y9 | M17: Y10
B18: =Input!B64 -> Orthopedics | C18: 0 | D18: =$D$14*Input!C64 -> 750 | E18: =E14*Input!$C64 -> 1312.5 | F18: =F14*Input!$C64 -> 1631.25 | G18: =G14*Input!$C64 -> 1680.1875 | H18: =H14*Input!$C64 -> 1730.5931 | I18: =I14*Input!$C64 -> 1782.5109 | J18: =J14*Input!$C64 -> 1835.9862 | K18: =K14*Input!$C64 -> 1891.0658 | L18: =L14*Input!$C64 -> 1947.7978 | M18: =M14*Input!$C64 -> 2006.2317
B19: =Input!B65 -> General Surgery | C19: 0 | D19: =$D$14*Input!C65 -> 600 | E19: =E$14*Input!$C65 -> 1050 | F19: =F14*Input!$C65 -> 1305 | G19: =G14*Input!$C65 -> 1344.15 | H19: =H14*Input!$C65 -> 1384.4745 | I19: =I14*Input!$C65 -> 1426.0087 | J19: =J14*Input!$C65 -> 1468.789 | K19: =K14*Input!$C65 -> 1512.8527 | L19: =L14*Input!$C65 -> 1558.2382 | M19: =M14*Input!$C65 -> 1604.9854
B20: =Input!B66 -> Urology | C20: 0 | D20: =$D$14*Input!C66 -> 450 | E20: =E$14*Input!$C66 -> 787.5 | F20: =F$14*Input!$C66 -> 978.75 | G20: =G$14*Input!$C66 -> 1008.1125 | H20: =H$14*Input!$C66 -> 1038.3559 | I20: =I$14*Input!$C66 -> 1069.5066 | J20: =J$14*Input!$C66 -> 1101.5917 | K20: =K$14*Input!$C66 -> 1134.6395 | L20: =L$14*Input!$C66 -> 1168.6787 | M20: =M$14*Input!$C66 -> 1203.739
B21: =Input!B67 -> OBGYN | C21: 0 | D21: =$D$14*Input!C67 -> 300 | E21: =E$14*Input!$C67 -> 525 | F21: =F$14*Input!$C67 -> 652.5 | G21: =G$14*Input!$C67 -> 672.075 | H21: =H$14*Input!$C67 -> 692.23725 | I21: =I$14*Input!$C67 -> 713.00437 | J21: =J$14*Input!$C67 -> 734.3945 | K21: =K$14*Input!$C67 -> 756.42633 | L21: =L$14*Input!$C67 -> 779.11912 | M21: =M$14*Input!$C67 -> 802.4927
B22: =Input!B68 -> ENT | C22: 0 | D22: =$D$14*Input!C68 -> 150 | E22: =E$14*Input!$C68 -> 262.5 | F22: =F$14*Input!$C68 -> 326.25 | G22: =G$14*Input!$C68 -> 336.0375 | H22: =H$14*Input!$C68 -> 346.11863 | I22: =I$14*Input!$C68 -> 356.50218 | J22: =J$14*Input!$C68 -> 367.19725 | K22: =K$14*Input!$C68 -> 378.21317 | L22: =L$14*Input!$C68 -> 389.55956 | M22: =M$14*Input!$C68 -> 401.24635
B23: =Input!B69 -> Ophthalmology | C23: 0 | D23: =$D$14*Input!C69 -> 150 | E23: =E$14*Input!$C69 -> 262.5 | F23: =F$14*Input!$C69 -> 326.25 | G23: =G$14*Input!$C69 -> 336.0375 | H23: =H$14*Input!$C69 -> 346.11863 | I23: =I$14*Input!$C69 -> 356.50218 | J23: =J$14*Input!$C69 -> 367.19725 | K23: =K$14*Input!$C69 -> 378.21317 | L23: =L$14*Input!$C69 -> 389.55956 | M23: =M$14*Input!$C69 -> 401.24635
B24: =Input!B70 -> GI Endoscopy (procedure rooms) | C24: 0 | D24: =$D$14*Input!C70 -> 600 | E24: =E$14*Input!$C70 -> 1050 | F24: =F$14*Input!$C70 -> 1305 | G24: =G$14*Input!$C70 -> 1344.15 | H24: =H$14*Input!$C70 -> 1384.4745 | I24: =I$14*Input!$C70 -> 1426.0087 | J24: =J$14*Input!$C70 -> 1468.789 | K24: =K$14*Input!$C70 -> 1512.8527 | L24: =L$14*Input!$C70 -> 1558.2382 | M24: =M$14*Input!$C70 -> 1604.9854
B25: Robotic Cases | C25: 0 | D25: =SUMPRODUCT(D18:D24,Input!$F$64:$F$70) -> 757.5 | E25: =SUMPRODUCT(E18:E24,Input!$F$64:$F$70) -> 1325.625 | F25: =SUMPRODUCT(F18:F24,Input!$F$64:$F$70) -> 1647.5625 | G25: =SUMPRODUCT(G18:G24,Input!$F$64:$F$70) -> 1696.9894 | H25: =SUMPRODUCT(H18:H24,Input!$F$64:$F$70) -> 1747.8991 | I25: =SUMPRODUCT(I18:I24,Input!$F$64:$F$70) -> 1800.336 | J25: =SUMPRODUCT(J18:J24,Input!$F$64:$F$70) -> 1854.3461 | K25: =SUMPRODUCT(K18:K24,Input!$F$64:$F$70) -> 1909.9765 | ... M25: =SUMPRODUCT(M18:M24,Input!$F$64:$F$70) -> 2026.2941

Sheet Revenue
B2: Revenue Model & Service Line Forecast
E5: Scenario Control | F5: 1
B7: Line Item | C7: Y0 | D7: Y1 | E7: Y2 | F7: Y3 | G7: Y4 | H7: Y5 | I7: Y6 | J7: Y7 | K7: Y8 | L7: Y9 | M7: Y10
B8: Payer-weighted | C8: 0 | D8: {=SUMPRODUCT(Input!$D$57:$D$60,TRANSPOSE(INDEX(Scenarios!$C$6:$F$10,Volume!$D$5,0)))} -> 1.088 | E8: {=SUMPRODUCT(Input!$D$57:$D$60,TRANSPOSE(INDEX(Scenarios!$C$6:$F$10,Volume!$D$5,0)))} -> 1.088 | F8: {=SUMPRODUCT(Input!$D$57:$D$60,TRANSPOSE(INDEX(Scenarios!$C$6:$F$10,Volume!$D$5,0)))} -> 1.088 | G8: {=SUMPRODUCT(Input!$D$57:$D$60,TRANSPOSE(INDEX(Scenarios!$C$6:$F$10,Volume!$D$5,0)))} -> 1.088 | H8: {=SUMPRODUCT(Input!$D$57:$D$60,TRANSPOSE(INDEX(Scenarios!$C$6:$F$10,Volume!$D$5,0)))} -> 1.088 | I8: {=SUMPRODUCT(Input!$D$57:$D$60,TRANSPOSE(INDEX(Scenarios!$C$6:$F$10,Volume!$D$5,0)))} -> 1.088 | J8: {=SUMPRODUCT(Input!$D$57:$D$60,TRANSPOSE(INDEX(Scenarios!$C$6:$F$10,Volume!$D$5,0)))} -> 1.088 | K8: {=SUMPRODUCT(Input!$D$57:$D$60,TRANSPOSE(INDEX(Scenarios!$C$6:$F$10,Volume!$D$5,0)))} -> 1.088 | ... M8: {=SUMPRODUCT(Input!$D$57:$D$60,TRANSPOSE(INDEX(Scenarios!$C$6:$F$10,Volume!$D$5,0)))} -> 1.088
B9: Total Revenue | C9: 0 | D9: =SUM(D13:D19) -> 28119360 | E9: =SUM(E13:E19) -> 76115970 | F9: =SUM(F13:F19) -> 97439315 | G9: =SUM(G13:G19) -> 1.0337337e+08 | H9: =SUM(H13:H19) -> 1.0966881e+08 | I9: =SUM(I13:I19) -> 1.1634764e+08 | J9: =SUM(J13:J19) -> 1.2343321e+08 | K9: =SUM(K13:K19) -> 1.3095029e+08 | ... M9: =SUM(M13:M19) -> 1.4738571e+08
B12: Revenue by Service Line | C12: Y0 | D12: Y1 | E12: Y2 | F12: Y3 | G12: Y4 | H12: Y5 | I12: Y6 | J12: Y7 | K12: Y8 | L12: Y9 | M12: Y10
B13: =Input!B64 -> Orthopedics | C13: 0 | D13: =D$8*Volume!D$18*Input!$D64 -> 12240000 | E13: =E$8*Volume!E$18*Input!$D64*(1+Input!$C$10)^1 -> 22062600 | F13: =F$8*Volume!F$18*Input!$D64*(1+Input!$C$10)^2 -> 28243280 | G13: =G$8*Volume!G$18*Input!$D64*(1+Input!$C$10)^3 -> 29963296 | H13: =H$8*Volume!H$18*Input!$D64*(1+Input!$C$10)^4 -> 31788060 | I13: =I$8*Volume!I$18*Input!$D64*(1+Input!$C$10)^5 -> 33723953 | J13: =J$8*Volume!J$18*Input!$D64*(1+Input!$C$10)^6 -> 35777742 | K13: =K$8*Volume!K$18*Input!$D64*(1+Input!$C$10)^7 -> 37956606 | L13: =L$8*Volume!L$18*Input!$D64*(1+Input!$C$10)^8 -> 40268164 | M13: =M$8*Volume!M$18*Input!$D64*(1+Input!$C$10)^9 -> 42720495
B14: =Input!B65 -> General Surgery | C14: 0 | D14: =D$8*Volume!D19*Input!D65 -> 4569600 | E14: =E$8*Volume!E$18*Input!$D65*(1+Input!$C$10)^1 -> 10295880 | F14: =F$8*Volume!F$18*Input!$D65*(1+Input!$C$10)^2 -> 13180197 | G14: =G$8*Volume!G$18*Input!$D65*(1+Input!$C$10)^3 -> 13982871 | H14: =H$8*Volume!H$18*Input!$D65*(1+Input!$C$10)^4 -> 14834428 | I14: =I$8*Volume!I$18*Input!$D65*(1+Input!$C$10)^5 -> 15737845 | J14: =J$8*Volume!J$18*Input!$D65*(1+Input!$C$10)^6 -> 16696280 | K14: =K$8*Volume!K$18*Input!$D65*(1+Input!$C$10)^7 -> 17713083 | L14: =L$8*Volume!L$18*Input!$D65*(1+Input!$C$10)^8 -> 18791810 | M14: =M$8*Volume!M$18*Input!$D65*(1+Input!$C$10)^9 -> 19936231
B15: =Input!B66 -> Urology | C15: 0 | D15: =D$8*Volume!D20*Input!D66 -> 6364800 | E15: =E$8*Volume!E$18*Input!$D66*(1+Input!$C$10)^1 -> 19120920 | F15: =F$8*Volume!F$18*Input!$D66*(1+Input!$C$10)^2 -> 24477509 | G15: =G$8*Volume!G$18*Input!$D66*(1+Input!$C$10)^3 -> 25968189 | H15: =H$8*Volume!H$18*Input!$D66*(1+Input!$C$10)^4 -> 27549652 | I15: =I$8*Volume!I$18*Input!$D66*(1+Input!$C$10)^5 -> 29227426 | J15: =J$8*Volume!J$18*Input!$D66*(1+Input!$C$10)^6 -> 31007376 | K15: =K$8*Volume!K$18*Input!$D66*(1+Input!$C$10)^7 -> 32895725 | L15: =L$8*Volume!L$18*Input!$D66*(1+Input!$C$10)^8 -> 34899075 | M15: =M$8*Volume!M$18*Input!$D66*(1+Input!$C$10)^9 -> 37024429
B16: =Input!B67 -> OBGYN | C16: 0 | D16: =D$8*Volume!D21*Input!D67 -> 3100800 | E16: =E$8*Volume!E$18*Input!$D67*(1+Input!$C$10)^1 -> 13972980 | F16: =F$8*Volume!F$18*Input!$D67*(1+Input!$C$10)^2 -> 17887411 | G16: =G$8*Volume!G$18*Input!$D67*(1+Input!$C$10)^3 -> 18976754 | H16: =H$8*Volume!H$18*Input!$D67*(1+Input!$C$10)^4 -> 20132438 | I16: =I$8*Volume!I$18*Input!$D67*(1+Input!$C$10)^5 -> 21358504 | J16: =J$8*Volume!J$18*Input!$D67*(1+Input!$C$10)^6 -> 22659237 | K16: =K$8*Volume!K$18*Input!$D67*(1+Input!$C$10)^7 -> 24039184 | L16: =L$8*Volume!L$18*Input!$D67*(1+Input!$C$10)^8 -> 25503170 | M16: =M$8*Volume!M$18*Input!$D67*(1+Input!$C$10)^9 -> 27056313
B17: =Input!B68 -> ENT | C17: 0 | D17: =D$8*Volume!D22*Input!D68 -> 636480 | E17: =E$8*Volume!E$18*Input!$D68*(1+Input!$C$10)^1 -> 5736276 | F17: =F$8*Volume!F$18*Input!$D68*(1+Input!$C$10)^2 -> 7343252.7 | G17: =G$8*Volume!G$18*Input!$D68*(1+Input!$C$10)^3 -> 7790456.8 | H17: =H$8*Volume!H$18*Input!$D68*(1+Input!$C$10)^4 -> 8264895.7 | I17: =I$8*Volume!I$18*Input!$D68*(1+Input!$C$10)^5 -> 8768227.8 | J17: =J$8*Volume!J$18*Input!$D68*(1+Input!$C$10)^6 -> 9302212.9 | K17: =K$8*Volume!K$18*Input!$D68*(1+Input!$C$10)^7 -> 9868717.6 | L17: =L$8*Volume!L$18*Input!$D68*(1+Input!$C$10)^8 -> 10469723 | M17: =M$8*Volume!M$18*Input!$D68*(1+Input!$C$10)^9 -> 11107329
B18: =Input!B69 -> Ophthalmology | C18: 0 | D18: =D$8*Volume!D23*Input!D69 -> 326400 | E18: =E$8*Volume!E$18*Input!$D69*(1+Input!$C$10)^1 -> 2941680 | F18: =F$8*Volume!F$18*Input!$D69*(1+Input!$C$10)^2 -> 3765770.6 | G18: =G$8*Volume!G$18*Input!$D69*(1+Input!$C$10)^3 -> 3995106.1 | H18: =H$8*Volume!H$18*Input!$D69*(1+Input!$C$10)^4 -> 4238408 | I18: =I$8*Volume!I$18*Input!$D69*(1+Input!$C$10)^5 -> 4496527.1 | J18: =J$8*Volume!J$18*Input!$D69*(1+Input!$C$10)^6 -> 4770365.6 | K18: =K$8*Volume!K$18*Input!$D69*(1+Input!$C$10)^7 -> 5060880.8 | L18: =L$8*Volume!L$18*Input!$D69*(1+Input!$C$10)^8 -> 5369088.5 | M18: =M$8*Volume!M$18*Input!$D69*(1+Input!$C$10)^9 -> 5696066
B19: =Input!B70 -> GI Endoscopy (procedure rooms) | C19: 0 | D19: =D$8*Volume!D24*Input!D70 -> 881280 | E19: =E$8*Volume!E$18*Input!$D70*(1+Input!$C$10)^1 -> 1985634 | F19: =F$8*Volume!F$18*Input!$D70*(1+Input!$C$10)^2 -> 2541895.2 | G19: =G$8*Volume!G$18*Input!$D70*(1+Input!$C$10)^3 -> 2696696.6 | H19: =H$8*Volume!H$18*Input!$D70*(1+Input!$C$10)^4 -> 2860925.4 | I19: =I$8*Volume!I$18*Input!$D70*(1+Input!$C$10)^5 -> 3035155.8 | J19: =J$8*Volume!J$18*Input!$D70*(1+Input!$C$10)^6 -> 3219996.8 | K19: =K$8*Volume!K$18*Input!$D70*(1+Input!$C$10)^7 -> 3416094.6 | L19: =L$8*Volume!L$18*Input!$D70*(1+Input!$C$10)^8 -> 3624134.7 | M19: =M$8*Volume!M$18*Input!$D70*(1+Input!$C$10)^9 -> 3844844.5

Sheet Opex
B2: Operating Cost Forecast
F5: Scenario Control
B7: Variable Cost By Specialty/Service Line | C7: Y0 | D7: Y1 | E7: Y2 | F7: Y3 | G7: Y4 | H7: Y5 | I7: Y6 | J7: Y7 | K7: Y8 | L7: Y9 | M7: Y10
B8: =Input!B64 -> Orthopedics | C8: 0 | D8: =Volume!D18*Input!$E64 -> 6750000 | E8: =Volume!E18*Input!$E64*(1+Input!$C$9)^1 -> 12166875 | F8: =Volume!F18*Input!$E64*(1+Input!$C$9)^2 -> 15575338 | G8: =Volume!G18*Input!$E64*(1+Input!$C$9)^3 -> 16523876 | H8: =Volume!H18*Input!$E64*(1+Input!$C$9)^4 -> 17530180 | I8: =Volume!I18*Input!$E64*(1+Input!$C$9)^5 -> 18597768 | J8: =Volume!J18*Input!$E64*(1+Input!$C$9)^6 -> 19730372 | K8: =Volume!K18*Input!$E64*(1+Input!$C$9)^7 -> 20931952 | L8: =Volume!L18*Input!$E64*(1+Input!$C$9)^8 -> 22206708 | M8: =Volume!M18*Input!$E64*(1+Input!$C$9)^9 -> 23559096
B9: =Input!B65 -> General Surgery | C9: 0 | D9: =Volume!D19*Input!E65 -> 1500000 | E9: =Volume!E19*Input!$E65*(1+Input!$C$9)^1 -> 2703750 | F9: =Volume!F19*Input!$E65*(1+Input!$C$9)^2 -> 3461186.2 | G9: =Volume!G19*Input!$E65*(1+Input!$C$9)^3 -> 3671972.5 | H9: =Volume!H19*Input!$E65*(1+Input!$C$9)^4 -> 3895595.6 | I9: =Volume!I19*Input!$E65*(1+Input!$C$9)^5 -> 4132837.4 | J9: =Volume!J19*Input!$E65*(1+Input!$C$9)^6 -> 4384527.2 | K9: =Volume!K19*Input!$E65*(1+Input!$C$9)^7 -> 4651544.9 | L9: =Volume!L19*Input!$E65*(1+Input!$C$9)^8 -> 4934824 | M9: =Volume!M19*Input!$E65*(1+Input!$C$9)^9 -> 5235354.8
B10: =Input!B66 -> Urology | C10: 0 | D10: =Volume!D20*Input!E66 -> 2475000 | E10: =Volume!E20*Input!$E66*(1+Input!$C$9)^1 -> 4461187.5 | F10: =Volume!F20*Input!$E66*(1+Input!$C$9)^2 -> 5710957.3 | G10: =Volume!G20*Input!$E66*(1+Input!$C$9)^3 -> 6058754.6 | H10: =Volume!H20*Input!$E66*(1+Input!$C$9)^4 -> 6427732.8 | I10: =Volume!I20*Input!$E66*(1+Input!$C$9)^5 -> 6819181.7 | J10: =Volume!J20*Input!$E66*(1+Input!$C$9)^6 -> 7234469.9 | K10: =Volume!K20*Input!$E66*(1+Input!$C$9)^7 -> 7675049.1 | L10: =Volume!L20*Input!$E66*(1+Input!$C$9)^8 -> 8142459.6 | M10: =Volume!M20*Input!$E66*(1+Input!$C$9)^9 -> 8638335.3
B11: =Input!B67 -> OBGYN | C11: 0 | D11: =Volume!D21*Input!E67 -> 1290000 | E11: =Volume!E21*Input!$E67*(1+Input!$C$9)^1 -> 2325225 | F11: =Volume!F21*Input!$E67*(1+Input!$C$9)^2 -> 2976620.2 | G11: =Volume!G21*Input!$E67*(1+Input!$C$9)^3 -> 3157896.3 | H11: =Volume!H21*Input!$E67*(1+Input!$C$9)^4 -> 3350212.2 | I11: =Volume!I21*Input!$E67*(1+Input!$C$9)^5 -> 3554240.2 | J11: =Volume!J21*Input!$E67*(1+Input!$C$9)^6 -> 3770693.4 | K11: =Volume!K21*Input!$E67*(1+Input!$C$9)^7 -> 4000328.6 | L11: =Volume!L21*Input!$E67*(1+Input!$C$9)^8 -> 4243948.6 | M11: =Volume!M21*Input!$E67*(1+Input!$C$9)^9 -> 4502405.1
B12: =Input!B68 -> ENT | C12: 0 | D12: =Volume!D22*Input!E68 -> 217500 | E12: =Volume!E22*Input!$E68*(1+Input!$C$9)^1 -> 392043.75 | F12: =Volume!F22*Input!$E68*(1+Input!$C$9)^2 -> 501872.01 | G12: =Volume!G22*Input!$E68*(1+Input!$C$9)^3 -> 532436.01 | H12: =Volume!H22*Input!$E68*(1+Input!$C$9)^4 -> 564861.36 | I12: =Volume!I22*Input!$E68*(1+Input!$C$9)^5 -> 599261.42 | J12: =Volume!J22*Input!$E68*(1+Input!$C$9)^6 -> 635756.44 | K12: =Volume!K22*Input!$E68*(1+Input!$C$9)^7 -> 674474.01 | L12: =Volume!L22*Input!$E68*(1+Input!$C$9)^8 -> 715549.48 | M12: =Volume!M22*Input!$E68*(1+Input!$C$9)^9 -> 759126.44
B13: =Input!B69 -> Ophthalmology | C13: 0 | D13: =Volume!D23*Input!E69 -> 127500 | E13: =Volume!E23*Input!$E69*(1+Input!$C$9)^1 -> 229818.75 | F13: =Volume!F23*Input!$E69*(1+Input!$C$9)^2 -> 294200.83 | G13: =Volume!G23*Input!$E69*(1+Input!$C$9)^3 -> 312117.66 | H13: =Volume!H23*Input!$E69*(1+Input!$C$9)^4 -> 331125.63 | I13: =Volume!I23*Input!$E69*(1+Input!$C$9)^5 -> 351291.18 | J13: =Volume!J23*Input!$E69*(1+Input!$C$9)^6 -> 372684.81 | K13: =Volume!K23*Input!$E69*(1+Input!$C$9)^7 -> 395381.32 | L13: =Volume!L23*Input!$E69*(1+Input!$C$9)^8 -> 419460.04 | M13: =Volume!M23*Input!$E69*(1+Input!$C$9)^9 -> 445005.15
B14: =Input!B70 -> GI Endoscopy (procedure rooms) | C14: 0 | D14: =Volume!D24*Input!E70 -> 366000 | E14: =Volume!E24*Input!$E70*(1+Input!$C$9)^1 -> 659715 | F14: =Volume!F24*Input!$E70*(1+Input!$C$9)^2 -> 844529.44 | G14: =Volume!G24*Input!$E70*(1+Input!$C$9)^3 -> 895961.29 | H14: =Volume!H24*Input!$E70*(1+Input!$C$9)^4 -> 950525.33 | I14: =Volume!I24*Input!$E70*(1+Input!$C$9)^5 -> 1008412.3 | J14: =Volume!J24*Input!$E70*(1+Input!$C$9)^6 -> 1069824.6 | K14: =Volume!K24*Input!$E70*(1+Input!$C$9)^7 -> 1134977 | L14: =Volume!L24*Input!$E70*(1+Input!$C$9)^8 -> 1204097.1 | M14: =Volume!M24*Input!$E70*(1+Input!$C$9)^9 -> 1277426.6
B15: Robotic Cases (Subset Of Delivered) | C15: 0 | D15: =Volume!D$25*Input!$C$37 -> 1136250 | E15: =Volume!E$25*Input!$C$37*(1+Input!C9)^1 -> 2048090.6 | F15: =Volume!F$25*Input!$C$37*(1+Input!$C$9)^2 -> 2621848.6 | G15: =Volume!G$25*Input!$C$37*(1+Input!$C$9)^3 -> 2781519.2 | H15: =Volume!H$25*Input!$C$37*(1+Input!$C$9)^4 -> 2950913.7 | I15: =Volume!I$25*Input!$C$37*(1+Input!$C$9)^5 -> 3130624.3 | J15: =Volume!J$25*Input!$C$37*(1+Input!$C$9)^6 -> 3321279.3 | K15: =Volume!K$25*Input!$C$37*(1+Input!$C$9)^7 -> 3523545.3 | L15: =Volume!L$25*Input!$C$37*(1+Input!$C$9)^8 -> 3738129.2 | M15: =Volume!M$25*Input!$C$37*(1+Input!$C$9)^9 -> 3965781.2
B17: Total Variable Costs | C17: 0 | D17: =SUM(D8:D15) -> 13862250 | E17: =SUM(E8:E15) -> 24986706 | F17: =SUM(F8:F15) -> 31986553 | G17: =SUM(G8:G15) -> 33934534 | H17: =SUM(H8:H15) -> 36001147 | I17: =SUM(I8:I15) -> 38193617 | J17: =SUM(J8:J15) -> 40519608 | K17: =SUM(K8:K15) -> 42987252 | ... M17: =SUM(M8:M15) -> 48382531
B19: Fixed Costs | C19: Y0 | D19: Y1 | E19: Y2 | F19: Y3 | G19: Y4 | H19: Y5 | I19: Y6 | J19: Y7 | K19: Y8 | L19: Y9 | M19: Y10
B20: Staffing Costs | C20: 0 | D20: =Input!$C$52 -> 7719680 | E20: =D20*(1+Input!$C$9) -> 7951270.4 | F20: =E20*(1+Input!$C$9) -> 8189808.5 | G20: =F20*(1+Input!$C$9) -> 8435502.8 | H20: =G20*(1+Input!$C$9) -> 8688567.9 | I20: =H20*(1+Input!$C$9) -> 8949224.9 | J20: =I20*(1+Input!$C$9) -> 9217701.6 | K20: =J20*(1+Input!$C$9) -> 9494232.7 | L20: =K20*(1+Input!$C$9) -> 9779059.7 | M20: =L20*(1+Input!$C$9) -> 10072431
B21: Facility Ops | C21: 0 | D21: =Revenue!D9*Input!$C$12 -> 1124774.4 | E21: =Revenue!E9*Input!$C$12*(1+Input!$C$12) -> 3166424.4 | F21: =Revenue!F9*Input!$C$12*(1+Input!$C$12) -> 4053475.5 | G21: =Revenue!G9*Input!$C$12*(1+Input!$C$12) -> 4300332.2 | H21: =Revenue!H9*Input!$C$12*(1+Input!$C$12) -> 4562222.4 | I21: =Revenue!I9*Input!$C$12*(1+Input!$C$12) -> 4840061.7 | J21: =Revenue!J9*Input!$C$12*(1+Input!$C$12) -> 5134821.5 | K21: =Revenue!K9*Input!$C$12*(1+Input!$C$12) -> 5447532.1 | L21: =Revenue!L9*Input!$C$12*(1+Input!$C$12) -> 5779286.8 | M21: =Revenue!M9*Input!$C$12*(1+Input!$C$12) -> 6131245.4
B22: Robot Service Contracts | C22: 0 | D22: =Input!$C$29*Input!$C$31 -> 300000 | E22: =D22*(1+Input!$C$9) -> 309000 | F22: =E22*(1+Input!$C$9) -> 318270 | G22: =F22*(1+Input!$C$9) -> 327818.1 | H22: =G22*(1+Input!$C$9) -> 337652.64 | I22: =H22*(1+Input!$C$9) -> 347782.22 | J22: =I22*(1+Input!$C$9) -> 358215.69 | K22: =J22*(1+Input!$C$9) -> 368962.16 | L22: =K22*(1+Input!$C$9) -> 380031.02 | M22: =L22*(1+Input!$C$9) -> 391431.96
B23: Marketing/Referral Development | C23: 0 | D23: =Input!C38 -> 300000 | E23: =D23*(1+Input!$C$9) -> 309000 | F23: =E23*(1+Input!$C$9) -> 318270 | G23: =F23*(1+Input!$C$9) -> 327818.1 | H23: =G23*(1+Input!$C$9) -> 337652.64 | I23: =H23*(1+Input!$C$9) -> 347782.22 | J23: =I23*(1+Input!$C$9) -> 358215.69 | K23: =J23*(1+Input!$C$9) -> 368962.16 | L23: =K23*(1+Input!$C$9) -> 380031.02 | M23: =L23*(1+Input!$C$9) -> 391431.96
B25: Total Fixed Costs | C25: 0 | D25: =SUM(D20:D23) -> 9444454.4 | E25: =SUM(E20:E23) -> 11735695 | F25: =SUM(F20:F23) -> 12879824 | G25: =SUM(G20:G23) -> 13391471 | H25: =SUM(H20:H23) -> 13926096 | I25: =SUM(I20:I23) -> 14484851 | J25: =SUM(J20:J23) -> 15068955 | K25: =SUM(K20:K23) -> 15679689 | ... M25: =SUM(M20:M23) -> 16986541
B26: Total Operating Costs (Fixed + Variable) | C26: 0 | D26: =D17+D25 -> 23306704 | E26: =E17+E25 -> 36722400 | F26: =F17+F25 -> 44866377 | G26: =G17+G25 -> 47326005 | H26: =H17+H25 -> 49927242 | I26: =I17+I25 -> 52678468 | J26: =J17+J25 -> 55588563 | K26: =K17+K25 -> 58666941 | ... M26: =M17+M25 -> 65369072

Sheet P&L
B2: Projected Profit & Loss Statement
F5: Scenario Control
B7: Line Item | C7: Y0 | D7: Y1 | E7: Y2 | F7: Y3 | G7: Y4 | H7: Y5 | I7: Y6 | J7: Y7 | K7: Y8 | L7: Y9 | M7: Y10
B8: Revenue | C8: 0 | D8: =Revenue!D9 -> 28119360 | E8: =Revenue!E9 -> 76115970 | F8: =Revenue!F9 -> 97439315 | G8: =Revenue!G9 -> 1.0337337e+08 | H8: =Revenue!H9 -> 1.0966881e+08 | I8: =Revenue!I9 -> 1.1634764e+08 | J8: =Revenue!J9 -> 1.2343321e+08 | K8: =Revenue!K9 -> 1.3095029e+08 | ... M8: =Revenue!M9 -> 1.4738571e+08
B10: Variable Costs | C10: 0 | D10: =-Opex!D17 -> -13862250 | E10: =-Opex!E17 -> -24986706 | F10: =-Opex!F17 -> -31986553 | G10: =-Opex!G17 -> -33934534 | H10: =-Opex!H17 -> -36001147 | I10: =-Opex!I17 -> -38193617 | J10: =-Opex!J17 -> -40519608 | K10: =-Opex!K17 -> -42987252 | ... M10: =-Opex!M17 -> -48382531
B11: Contribution Margin | C11: 0 | D11: =SUM(D8:D10) -> 14257110 | E11: =SUM(E8:E10) -> 51129264 | F11: =SUM(F8:F10) -> 65452763 | G11: =SUM(G8:G10) -> 69438836 | H11: =SUM(H8:H10) -> 73667661 | I11: =SUM(I8:I10) -> 78154021 | J11: =SUM(J8:J10) -> 82913601 | K11: =SUM(K8:K10) -> 87963040 | ... M11: =SUM(M8:M10) -> 99003176
B12: Fixed Costs | C12: 0 | D12: =-Opex!D25 -> -9444454.4 | E12: =-Opex!E25 -> -11735695 | F12: =-Opex!F25 -> -12879824 | G12: =-Opex!G25 -> -13391471 | H12: =-Opex!H25 -> -13926096 | I12: =-Opex!I25 -> -14484851 | J12: =-Opex!J25 -> -15068955 | K12: =-Opex!K25 -> -15679689 | ... M12: =-Opex!M25 -> -16986541
B13: EBITDA | C13: 0 | D13: =SUM(D11:D12) -> 4812655.6 | E13: =SUM(E11:E12) -> 39393570 | F13: =SUM(F11:F12) -> 52572939 | G13: =SUM(G11:G12) -> 56047365 | H13: =SUM(H11:H12) -> 59741565 | I13: =SUM(I11:I12) -> 63669170 | J13: =SUM(J11:J12) -> 67844647 | K13: =SUM(K11:K12) -> 72283351 | ... M13: =SUM(M11:M12) -> 82016635
B15: Depreciation | C15: 0 | D15: =-Capex!D22 -> -1793500 | E15: =-Capex!E22 -> -1793500 | F15: =-Capex!F22 -> -1793500 | G15: =-Capex!G22 -> -1793500 | H15: =-Capex!H22 -> -1793500 | I15: =-Capex!I22 -> -1793500 | J15: =-Capex!J22 -> -1793500 | K15: =-Capex!K22 -> -1793500 | ... M15: =-Capex!M22 -> -1793500
B16: EBIT | C16: 0 | D16: =SUM(D13:D15) -> 3019155.6 | E16: =SUM(E13:E15) -> 37600070 | F16: =SUM(F13:F15) -> 50779439 | G16: =SUM(G13:G15) -> 54253865 | H16: =SUM(H13:H15) -> 57948065 | I16: =SUM(I13:I15) -> 61875670 | J16: =SUM(J13:J15) -> 66051147 | K16: =SUM(K13:K15) -> 70489851 | ... M16: =SUM(M13:M15) -> 80223135
B18: Taxes | C18: 0 | D18: =D16*-Input!$C$8 -> -754788.9 | E18: =E16*-Input!$C$8 -> -9400017.4 | F18: =F16*-Input!$C$8 -> -12694860 | G18: =G16*-Input!$C$8 -> -13563466 | H18: =H16*-Input!$C$8 -> -14487016 | I18: =I16*-Input!$C$8 -> -15468918 | J18: =J16*-Input!$C$8 -> -16512787 | K18: =K16*-Input!$C$8 -> -17622463 | ... M18: =M16*-Input!$C$8 -> -20055784
B19: NOPAT | C19: 0 | D19: =SUM(D16:D18) -> 2264366.7 | E19: =SUM(E16:E18) -> 28200052 | F19: =SUM(F16:F18) -> 38084579 | G19: =SUM(G16:G18) -> 40690399 | H19: =SUM(H16:H18) -> 43461049 | I19: =SUM(I16:I18) -> 46406753 | J19: =SUM(J16:J18) -> 49538360 | K19: =SUM(K16:K18) -> 52867388 | ... M19: =SUM(M16:M18) -> 60167352
B21: EBITDA Margin | C21: 0 | D21: =D13/D8 -> 0.17115097 | E21: =E13/E8 -> 0.51754671 | F21: =F13/F8 -> 0.53954544 | G21: =G13/G8 -> 0.54218378 | H21: =H13/H8 -> 0.54474528 | I21: =I13/I8 -> 0.54723217 | J21: =J13/J8 -> 0.54964662 | K21: =K13/K8 -> 0.55199076 | ... M21: =M13/M8 -> 0.55647618

Sheet Cash Flow
B2: Unlevered Free Cash Flow Schedule
F5: Scenario Control
B7: Line Item | C7: Y0 | D7: Y1 | E7: Y2 | F7: Y3 | G7: Y4 | H7: Y5 | I7: Y6 | J7: Y7 | K7: Y8 | L7: Y9 | M7: Y10
B8: NOPTA | C8: 0 | D8: ='P&L'!D19 -> 2264366.7 | E8: ='P&L'!E19 -> 28200052 | F8: ='P&L'!F19 -> 38084579 | G8: ='P&L'!G19 -> 40690399 | H8: ='P&L'!H19 -> 43461049 | I8: ='P&L'!I19 -> 46406753 | J8: ='P&L'!J19 -> 49538360 | K8: ='P&L'!K19 -> 52867388 | ... M8: ='P&L'!M19 -> 60167352
B9: Add Back Depreciation | C9: 0 | D9: =-'P&L'!D15 -> 1793500 | E9: =-'P&L'!E15 -> 1793500 | F9: =-'P&L'!F15 -> 1793500 | G9: =-'P&L'!G15 -> 1793500 | H9: =-'P&L'!H15 -> 1793500 | I9: =-'P&L'!I15 -> 1793500 | J9: =-'P&L'!J15 -> 1793500 | K9: =-'P&L'!K15 -> 1793500 | ... M9: =-'P&L'!M15 -> 1793500
B10: Change In Net Working Capital | C10: 0 | D10: =-Input!$C$34*Revenue!D9 -> -562387.2 | E10: =-Input!$C$34*Revenue!E9 -> -1522319.4 | F10: =-Input!$C$34*Revenue!F9 -> -1948786.3 | G10: =-Input!$C$34*Revenue!G9 -> -2067467.4 | H10: =-Input!$C$34*Revenue!H9 -> -2193376.2 | I10: =-Input!$C$34*Revenue!I9 -> -2326952.8 | J10: =-Input!$C$34*Revenue!J9 -> -2468664.2 | K10: =-Input!$C$34*Revenue!K9 -> -2619005.8 | ... M10: =-Input!$C$34*Revenue!M9 -> -2947714.1
B11: Capex | C11: =-Capex!C14 -> -35874250 | D11: =-Capex!D14 -> 0 | E11: =-Capex!E14 -> 0 | F11: =-Capex!F14 -> 0 | G11: =-Capex!G14 -> 0 | H11: =-Capex!H14 -> 0 | I11: =-Capex!I14 -> 0 | J11: =-Capex!J14 -> 0 | ... M11: =-Capex!M14 -> 0
B12: Free Cash Flow | C12: =SUM(C8:C11) -> -35874250 | D12: =SUM(D8:D11) -> 3495479.5 | E12: =SUM(E8:E11) -> 28471233 | F12: =SUM(F8:F11) -> 37929293 | G12: =SUM(G8:G11) -> 40416431 | H12: =SUM(H8:H11) -> 43061173 | I12: =SUM(I8:I11) -> 45873300 | J12: =SUM(J8:J11) -> 48863196 | ... M12: =SUM(M8:M11) -> 59013137
C13: 0
B14: Cumulative FCF | C14: =C12 -> -35874250 | D14: =C14+D12 -> -32378770 | E14: =D14+E12 -> -3907537.7 | F14: =E14+F12 -> 34021755 | G14: =F14+G12 -> 74438186 | H14: =G14+H12 -> 1.1749936e+08 | I14: =H14+I12 -> 1.6337266e+08 | J14: =I14+J12 -> 2.1223585e+08 | K14: =J14+K12 -> 2.6427774e+08 | ... M14: =L14+M12 -> 3.7871193e+08

Sheet DCF
B2: Discounted Cash Flow Valuation Summary
F5: Scenario Control
B7: Line Item | C7: Y0 | D7: Y1 | E7: Y2 | F7: Y3 | G7: Y4 | H7: Y5 | I7: Y6 | J7: Y7 | K7: Y8 | L7: Y9 | M7: Y10
B8: Free Chash Flow | C8: ='Cash Flow'!C12 -> -35874250 | D8: ='Cash Flow'!D12 -> 3495479.5 | E8: ='Cash Flow'!E12 -> 28471233 | F8: ='Cash Flow'!F12 -> 37929293 | G8: ='Cash Flow'!G12 -> 40416431 | H8: ='Cash Flow'!H12 -> 43061173 | I8: ='Cash Flow'!I12 -> 45873300 | J8: ='Cash Flow'!J12 -> 48863196 | ... M8: ='Cash Flow'!M12 -> 59013137
B9: Discount Factor | C9: =1/(1+Input!$C$7)^0 -> 1 | D9: =1/(1+Input!$C$7)^1 -> 0.89285714 | E9: =1/(1+Input!$C$7)^2 -> 0.79719388 | F9: =1/(1+Input!$C$7)^3 -> 0.71178025 | G9: =1/(1+Input!$C$7)^3 -> 0.71178025 | H9: =1/(1+Input!$C$7)^4 -> 0.63551808 | I9: =1/(1+Input!$C$7)^5 -> 0.56742686 | J9: =1/(1+Input!$C$7)^6 -> 0.50663112 | K9: =1/(1+Input!$C$7)^7 -> 0.45234922 | L9: =1/(1+Input!$C$7)^8 -> 0.40388323 | M9: =1/(1+Input!$C$7)^9 -> 0.36061002
B10: Present Value Of FC | C10: =C8*C9 -> -35874250 | D10: =D8*D9 -> 3120963.8 | E10: =E8*E9 -> 22697092 | F10: =F8*F9 -> 26997321 | G10: =G8*G9 -> 28767617 | H10: =H8*H9 -> 27366154 | I10: =I8*I9 -> 26029742 | J10: =J8*J9 -> 24755616 | ... M10: =M8*M9 -> 21280729
B12: NPV | C12: {=NPV(Input!C7,DCF!D8:M8+DCF!C8)} -> 5586255.4
